Assignment1 - C++/grader/tests/intermediate-add-add-race.in

    # When add order timestamp is not taken when the lock is acquired,
    # then the buys may end up in the linked list
    # in an order that does not match the timestamp order.

    # This is an easier version with only 2 buy threads
    
2
o
0 B 0 GOOG 2700 1
1 B 1 GOOG 2700 1
0 B 2 GOOG 2700 1
1 B 3 GOOG 2700 1
0 B 4 GOOG 2700 1
1 B 5 GOOG 2700 1
0 B 6 GOOG 2700 1
1 B 7 GOOG 2700 1
0 B 8 GOOG 2700 1
1 B 9 GOOG 2700 1
0 B 10 GOOG 2700 1
1 B 11 GOOG 2700 1
0 B 12 GOOG 2700 1
1 B 13 GOOG 2700 1
0 B 14 GOOG 2700 1
1 B 15 GOOG 2700 1
0 B 16 GOOG 2700 1
1 B 17 GOOG 2700 1
0 B 18 GOOG 2700 1
1 B 19 GOOG 2700 1
0 B 20 GOOG 2700 1
1 B 21 GOOG 2700 1
0 B 22 GOOG 2700 1
1 B 23 GOOG 2700 1
0 B 24 GOOG 2700 1
1 B 25 GOOG 2700 1
0 B 26 GOOG 2700 1
1 B 27 GOOG 2700 1
0 B 28 GOOG 2700 1
1 B 29 GOOG 2700 1
0 B 30 GOOG 2700 1
1 B 31 GOOG 2700 1
0 B 32 GOOG 2700 1
1 B 33 GOOG 2700 1
0 B 34 GOOG 2700 1
1 B 35 GOOG 2700 1
0 B 36 GOOG 2700 1
1 B 37 GOOG 2700 1
0 B 38 GOOG 2700 1
1 B 39 GOOG 2700 1
0 B 40 GOOG 2700 1
1 B 41 GOOG 2700 1
0 B 42 GOOG 2700 1
1 B 43 GOOG 2700 1
0 B 44 GOOG 2700 1
1 B 45 GOOG 2700 1
0 B 46 GOOG 2700 1
1 B 47 GOOG 2700 1
0 B 48 GOOG 2700 1
1 B 49 GOOG 2700 1
0 B 50 GOOG 2700 1
1 B 51 GOOG 2700 1
0 B 52 GOOG 2700 1
1 B 53 GOOG 2700 1
0 B 54 GOOG 2700 1
1 B 55 GOOG 2700 1
0 B 56 GOOG 2700 1
1 B 57 GOOG 2700 1
0 B 58 GOOG 2700 1
1 B 59 GOOG 2700 1
0 B 60 GOOG 2700 1
1 B 61 GOOG 2700 1
0 B 62 GOOG 2700 1
1 B 63 GOOG 2700 1
0 B 64 GOOG 2700 1
1 B 65 GOOG 2700 1
0 B 66 GOOG 2700 1
1 B 67 GOOG 2700 1
0 B 68 GOOG 2700 1
1 B 69 GOOG 2700 1
0 B 70 GOOG 2700 1
1 B 71 GOOG 2700 1
0 B 72 GOOG 2700 1
1 B 73 GOOG 2700 1
0 B 74 GOOG 2700 1
1 B 75 GOOG 2700 1
0 B 76 GOOG 2700 1
1 B 77 GOOG 2700 1
0 B 78 GOOG 2700 1
1 B 79 GOOG 2700 1
0 B 80 GOOG 2700 1
1 B 81 GOOG 2700 1
0 B 82 GOOG 2700 1
1 B 83 GOOG 2700 1
0 B 84 GOOG 2700 1
1 B 85 GOOG 2700 1
0 B 86 GOOG 2700 1
1 B 87 GOOG 2700 1
0 B 88 GOOG 2700 1
1 B 89 GOOG 2700 1
0 B 90 GOOG 2700 1
1 B 91 GOOG 2700 1
0 B 92 GOOG 2700 1
1 B 93 GOOG 2700 1
0 B 94 GOOG 2700 1
1 B 95 GOOG 2700 1
0 B 96 GOOG 2700 1
1 B 97 GOOG 2700 1
0 B 98 GOOG 2700 1
1 B 99 GOOG 2700 1
0 B 100 GOOG 2700 1
1 B 101 GOOG 2700 1
0 B 102 GOOG 2700 1
1 B 103 GOOG 2700 1
0 B 104 GOOG 2700 1
1 B 105 GOOG 2700 1
0 B 106 GOOG 2700 1
1 B 107 GOOG 2700 1
0 B 108 GOOG 2700 1
1 B 109 GOOG 2700 1
0 B 110 GOOG 2700 1
1 B 111 GOOG 2700 1
0 B 112 GOOG 2700 1
1 B 113 GOOG 2700 1
0 B 114 GOOG 2700 1
1 B 115 GOOG 2700 1
0 B 116 GOOG 2700 1
1 B 117 GOOG 2700 1
0 B 118 GOOG 2700 1
1 B 119 GOOG 2700 1
0 B 120 GOOG 2700 1
1 B 121 GOOG 2700 1
0 B 122 GOOG 2700 1
1 B 123 GOOG 2700 1
0 B 124 GOOG 2700 1
1 B 125 GOOG 2700 1
0 B 126 GOOG 2700 1
1 B 127 GOOG 2700 1
0 B 128 GOOG 2700 1
1 B 129 GOOG 2700 1
0 B 130 GOOG 2700 1
1 B 131 GOOG 2700 1
0 B 132 GOOG 2700 1
1 B 133 GOOG 2700 1
0 B 134 GOOG 2700 1
1 B 135 GOOG 2700 1
0 B 136 GOOG 2700 1
1 B 137 GOOG 2700 1
0 B 138 GOOG 2700 1
1 B 139 GOOG 2700 1
0 B 140 GOOG 2700 1
1 B 141 GOOG 2700 1
0 B 142 GOOG 2700 1
1 B 143 GOOG 2700 1
0 B 144 GOOG 2700 1
1 B 145 GOOG 2700 1
0 B 146 GOOG 2700 1
1 B 147 GOOG 2700 1
0 B 148 GOOG 2700 1
1 B 149 GOOG 2700 1
0 B 150 GOOG 2700 1
1 B 151 GOOG 2700 1
0 B 152 GOOG 2700 1
1 B 153 GOOG 2700 1
0 B 154 GOOG 2700 1
1 B 155 GOOG 2700 1
0 B 156 GOOG 2700 1
1 B 157 GOOG 2700 1
0 B 158 GOOG 2700 1
1 B 159 GOOG 2700 1
0 B 160 GOOG 2700 1
1 B 161 GOOG 2700 1
0 B 162 GOOG 2700 1
1 B 163 GOOG 2700 1
0 B 164 GOOG 2700 1
1 B 165 GOOG 2700 1
0 B 166 GOOG 2700 1
1 B 167 GOOG 2700 1
0 B 168 GOOG 2700 1
1 B 169 GOOG 2700 1
0 B 170 GOOG 2700 1
1 B 171 GOOG 2700 1
0 B 172 GOOG 2700 1
1 B 173 GOOG 2700 1
0 B 174 GOOG 2700 1
1 B 175 GOOG 2700 1
0 B 176 GOOG 2700 1
1 B 177 GOOG 2700 1
0 B 178 GOOG 2700 1
1 B 179 GOOG 2700 1
0 B 180 GOOG 2700 1
1 B 181 GOOG 2700 1
0 B 182 GOOG 2700 1
1 B 183 GOOG 2700 1
0 B 184 GOOG 2700 1
1 B 185 GOOG 2700 1
0 B 186 GOOG 2700 1
1 B 187 GOOG 2700 1
0 B 188 GOOG 2700 1
1 B 189 GOOG 2700 1
0 B 190 GOOG 2700 1
1 B 191 GOOG 2700 1
0 B 192 GOOG 2700 1
1 B 193 GOOG 2700 1
0 B 194 GOOG 2700 1
1 B 195 GOOG 2700 1
0 B 196 GOOG 2700 1
1 B 197 GOOG 2700 1
0 B 198 GOOG 2700 1
1 B 199 GOOG 2700 1
0 B 200 GOOG 2700 1
1 B 201 GOOG 2700 1
0 B 202 GOOG 2700 1
1 B 203 GOOG 2700 1
0 B 204 GOOG 2700 1
1 B 205 GOOG 2700 1
0 B 206 GOOG 2700 1
1 B 207 GOOG 2700 1
0 B 208 GOOG 2700 1
1 B 209 GOOG 2700 1
0 B 210 GOOG 2700 1
1 B 211 GOOG 2700 1
0 B 212 GOOG 2700 1
1 B 213 GOOG 2700 1
0 B 214 GOOG 2700 1
1 B 215 GOOG 2700 1
0 B 216 GOOG 2700 1
1 B 217 GOOG 2700 1
0 B 218 GOOG 2700 1
1 B 219 GOOG 2700 1
0 B 220 GOOG 2700 1
1 B 221 GOOG 2700 1
0 B 222 GOOG 2700 1
1 B 223 GOOG 2700 1
0 B 224 GOOG 2700 1
1 B 225 GOOG 2700 1
0 B 226 GOOG 2700 1
1 B 227 GOOG 2700 1
0 B 228 GOOG 2700 1
1 B 229 GOOG 2700 1
0 B 230 GOOG 2700 1
1 B 231 GOOG 2700 1
0 B 232 GOOG 2700 1
1 B 233 GOOG 2700 1
0 B 234 GOOG 2700 1
1 B 235 GOOG 2700 1
0 B 236 GOOG 2700 1
1 B 237 GOOG 2700 1
0 B 238 GOOG 2700 1
1 B 239 GOOG 2700 1
0 B 240 GOOG 2700 1
1 B 241 GOOG 2700 1
0 B 242 GOOG 2700 1
1 B 243 GOOG 2700 1
0 B 244 GOOG 2700 1
1 B 245 GOOG 2700 1
0 B 246 GOOG 2700 1
1 B 247 GOOG 2700 1
0 B 248 GOOG 2700 1
1 B 249 GOOG 2700 1
0 B 250 GOOG 2700 1
1 B 251 GOOG 2700 1
0 B 252 GOOG 2700 1
1 B 253 GOOG 2700 1
0 B 254 GOOG 2700 1
1 B 255 GOOG 2700 1
0 B 256 GOOG 2700 1
1 B 257 GOOG 2700 1
0 B 258 GOOG 2700 1
1 B 259 GOOG 2700 1
0 B 260 GOOG 2700 1
1 B 261 GOOG 2700 1
0 B 262 GOOG 2700 1
1 B 263 GOOG 2700 1
0 B 264 GOOG 2700 1
1 B 265 GOOG 2700 1
0 B 266 GOOG 2700 1
1 B 267 GOOG 2700 1
0 B 268 GOOG 2700 1
1 B 269 GOOG 2700 1
0 B 270 GOOG 2700 1
1 B 271 GOOG 2700 1
0 B 272 GOOG 2700 1
1 B 273 GOOG 2700 1
0 B 274 GOOG 2700 1
1 B 275 GOOG 2700 1
0 B 276 GOOG 2700 1
1 B 277 GOOG 2700 1
0 B 278 GOOG 2700 1
1 B 279 GOOG 2700 1
0 B 280 GOOG 2700 1
1 B 281 GOOG 2700 1
0 B 282 GOOG 2700 1
1 B 283 GOOG 2700 1
0 B 284 GOOG 2700 1
1 B 285 GOOG 2700 1
0 B 286 GOOG 2700 1
1 B 287 GOOG 2700 1
0 B 288 GOOG 2700 1
1 B 289 GOOG 2700 1
0 B 290 GOOG 2700 1
1 B 291 GOOG 2700 1
0 B 292 GOOG 2700 1
1 B 293 GOOG 2700 1
0 B 294 GOOG 2700 1
1 B 295 GOOG 2700 1
0 B 296 GOOG 2700 1
1 B 297 GOOG 2700 1
0 B 298 GOOG 2700 1
1 B 299 GOOG 2700 1
0 B 300 GOOG 2700 1
1 B 301 GOOG 2700 1
0 B 302 GOOG 2700 1
1 B 303 GOOG 2700 1
0 B 304 GOOG 2700 1
1 B 305 GOOG 2700 1
0 B 306 GOOG 2700 1
1 B 307 GOOG 2700 1
0 B 308 GOOG 2700 1
1 B 309 GOOG 2700 1
0 B 310 GOOG 2700 1
1 B 311 GOOG 2700 1
0 B 312 GOOG 2700 1
1 B 313 GOOG 2700 1
0 B 314 GOOG 2700 1
1 B 315 GOOG 2700 1
0 B 316 GOOG 2700 1
1 B 317 GOOG 2700 1
0 B 318 GOOG 2700 1
1 B 319 GOOG 2700 1
0 B 320 GOOG 2700 1
1 B 321 GOOG 2700 1
0 B 322 GOOG 2700 1
1 B 323 GOOG 2700 1
0 B 324 GOOG 2700 1
1 B 325 GOOG 2700 1
0 B 326 GOOG 2700 1
1 B 327 GOOG 2700 1
0 B 328 GOOG 2700 1
1 B 329 GOOG 2700 1
0 B 330 GOOG 2700 1
1 B 331 GOOG 2700 1
0 B 332 GOOG 2700 1
1 B 333 GOOG 2700 1
0 B 334 GOOG 2700 1
1 B 335 GOOG 2700 1
0 B 336 GOOG 2700 1
1 B 337 GOOG 2700 1
0 B 338 GOOG 2700 1
1 B 339 GOOG 2700 1
0 B 340 GOOG 2700 1
1 B 341 GOOG 2700 1
0 B 342 GOOG 2700 1
1 B 343 GOOG 2700 1
0 B 344 GOOG 2700 1
1 B 345 GOOG 2700 1
0 B 346 GOOG 2700 1
1 B 347 GOOG 2700 1
0 B 348 GOOG 2700 1
1 B 349 GOOG 2700 1
0 B 350 GOOG 2700 1
1 B 351 GOOG 2700 1
0 B 352 GOOG 2700 1
1 B 353 GOOG 2700 1
0 B 354 GOOG 2700 1
1 B 355 GOOG 2700 1
0 B 356 GOOG 2700 1
1 B 357 GOOG 2700 1
0 B 358 GOOG 2700 1
1 B 359 GOOG 2700 1
0 B 360 GOOG 2700 1
1 B 361 GOOG 2700 1
0 B 362 GOOG 2700 1
1 B 363 GOOG 2700 1
0 B 364 GOOG 2700 1
1 B 365 GOOG 2700 1
0 B 366 GOOG 2700 1
1 B 367 GOOG 2700 1
0 B 368 GOOG 2700 1
1 B 369 GOOG 2700 1
0 B 370 GOOG 2700 1
1 B 371 GOOG 2700 1
0 B 372 GOOG 2700 1
1 B 373 GOOG 2700 1
0 B 374 GOOG 2700 1
1 B 375 GOOG 2700 1
0 B 376 GOOG 2700 1
1 B 377 GOOG 2700 1
0 B 378 GOOG 2700 1
1 B 379 GOOG 2700 1
0 B 380 GOOG 2700 1
1 B 381 GOOG 2700 1
0 B 382 GOOG 2700 1
1 B 383 GOOG 2700 1
0 B 384 GOOG 2700 1
1 B 385 GOOG 2700 1
0 B 386 GOOG 2700 1
1 B 387 GOOG 2700 1
0 B 388 GOOG 2700 1
1 B 389 GOOG 2700 1
0 B 390 GOOG 2700 1
1 B 391 GOOG 2700 1
0 B 392 GOOG 2700 1
1 B 393 GOOG 2700 1
