Assignment1 - C++/grader/tests/intermediate-exec.in

    # Adds a pair of matchable concurrent orders, waits for it to exec, and loops
    
2
o
0 B 0 GOOG 2700 1
1 S 1 GOOG 2700 1
0 w 1
1 w 0
0 B 2 GOOG 2700 1
1 S 3 GOOG 2700 1
0 w 3
1 w 2
0 B 4 GOOG 2700 1
1 S 5 GOOG 2700 1
0 w 5
1 w 4
0 B 6 GOOG 2700 1
1 S 7 GOOG 2700 1
0 w 7
1 w 6
0 B 8 GOOG 2700 1
1 S 9 GOOG 2700 1
0 w 9
1 w 8
0 B 10 GOOG 2700 1
1 S 11 GOOG 2700 1
0 w 11
1 w 10
0 B 12 GOOG 2700 1
1 S 13 GOOG 2700 1
0 w 13
1 w 12
0 B 14 GOOG 2700 1
1 S 15 GOOG 2700 1
0 w 15
1 w 14
0 B 16 GOOG 2700 1
1 S 17 GOOG 2700 1
0 w 17
1 w 16
0 B 18 GOOG 2700 1
1 S 19 GOOG 2700 1
0 w 19
1 w 18
0 B 20 GOOG 2700 1
1 S 21 GOOG 2700 1
0 w 21
1 w 20
0 B 22 GOOG 2700 1
1 S 23 GOOG 2700 1
0 w 23
1 w 22
0 B 24 GOOG 2700 1
1 S 25 GOOG 2700 1
0 w 25
1 w 24
0 B 26 GOOG 2700 1
1 S 27 GOOG 2700 1
0 w 27
1 w 26
0 B 28 GOOG 2700 1
1 S 29 GOOG 2700 1
0 w 29
1 w 28
0 B 30 GOOG 2700 1
1 S 31 GOOG 2700 1
0 w 31
1 w 30
0 B 32 GOOG 2700 1
1 S 33 GOOG 2700 1
0 w 33
1 w 32
0 B 34 GOOG 2700 1
1 S 35 GOOG 2700 1
0 w 35
1 w 34
0 B 36 GOOG 2700 1
1 S 37 GOOG 2700 1
0 w 37
1 w 36
0 B 38 GOOG 2700 1
1 S 39 GOOG 2700 1
0 w 39
1 w 38
0 B 40 GOOG 2700 1
1 S 41 GOOG 2700 1
0 w 41
1 w 40
0 B 42 GOOG 2700 1
1 S 43 GOOG 2700 1
0 w 43
1 w 42
0 B 44 GOOG 2700 1
1 S 45 GOOG 2700 1
0 w 45
1 w 44
0 B 46 GOOG 2700 1
1 S 47 GOOG 2700 1
0 w 47
1 w 46
0 B 48 GOOG 2700 1
1 S 49 GOOG 2700 1
0 w 49
1 w 48
0 B 50 GOOG 2700 1
1 S 51 GOOG 2700 1
0 w 51
1 w 50
0 B 52 GOOG 2700 1
1 S 53 GOOG 2700 1
0 w 53
1 w 52
0 B 54 GOOG 2700 1
1 S 55 GOOG 2700 1
0 w 55
1 w 54
0 B 56 GOOG 2700 1
1 S 57 GOOG 2700 1
0 w 57
1 w 56
0 B 58 GOOG 2700 1
1 S 59 GOOG 2700 1
0 w 59
1 w 58
0 B 60 GOOG 2700 1
1 S 61 GOOG 2700 1
0 w 61
1 w 60
0 B 62 GOOG 2700 1
1 S 63 GOOG 2700 1
0 w 63
1 w 62
0 B 64 GOOG 2700 1
1 S 65 GOOG 2700 1
0 w 65
1 w 64
0 B 66 GOOG 2700 1
1 S 67 GOOG 2700 1
0 w 67
1 w 66
0 B 68 GOOG 2700 1
1 S 69 GOOG 2700 1
0 w 69
1 w 68
0 B 70 GOOG 2700 1
1 S 71 GOOG 2700 1
0 w 71
1 w 70
0 B 72 GOOG 2700 1
1 S 73 GOOG 2700 1
0 w 73
1 w 72
0 B 74 GOOG 2700 1
1 S 75 GOOG 2700 1
0 w 75
1 w 74
0 B 76 GOOG 2700 1
1 S 77 GOOG 2700 1
0 w 77
1 w 76
0 B 78 GOOG 2700 1
1 S 79 GOOG 2700 1
0 w 79
1 w 78
0 B 80 GOOG 2700 1
1 S 81 GOOG 2700 1
0 w 81
1 w 80
0 B 82 GOOG 2700 1
1 S 83 GOOG 2700 1
0 w 83
1 w 82
0 B 84 GOOG 2700 1
1 S 85 GOOG 2700 1
0 w 85
1 w 84
0 B 86 GOOG 2700 1
1 S 87 GOOG 2700 1
0 w 87
1 w 86
0 B 88 GOOG 2700 1
1 S 89 GOOG 2700 1
0 w 89
1 w 88
0 B 90 GOOG 2700 1
1 S 91 GOOG 2700 1
0 w 91
1 w 90
0 B 92 GOOG 2700 1
1 S 93 GOOG 2700 1
0 w 93
1 w 92
0 B 94 GOOG 2700 1
1 S 95 GOOG 2700 1
0 w 95
1 w 94
0 B 96 GOOG 2700 1
1 S 97 GOOG 2700 1
0 w 97
1 w 96
0 B 98 GOOG 2700 1
1 S 99 GOOG 2700 1
0 w 99
1 w 98
0 B 100 GOOG 2700 1
1 S 101 GOOG 2700 1
0 w 101
1 w 100
0 B 102 GOOG 2700 1
1 S 103 GOOG 2700 1
0 w 103
1 w 102
0 B 104 GOOG 2700 1
1 S 105 GOOG 2700 1
0 w 105
1 w 104
0 B 106 GOOG 2700 1
1 S 107 GOOG 2700 1
0 w 107
1 w 106
0 B 108 GOOG 2700 1
1 S 109 GOOG 2700 1
0 w 109
1 w 108
0 B 110 GOOG 2700 1
1 S 111 GOOG 2700 1
0 w 111
1 w 110
0 B 112 GOOG 2700 1
1 S 113 GOOG 2700 1
0 w 113
1 w 112
0 B 114 GOOG 2700 1
1 S 115 GOOG 2700 1
0 w 115
1 w 114
0 B 116 GOOG 2700 1
1 S 117 GOOG 2700 1
0 w 117
1 w 116
0 B 118 GOOG 2700 1
1 S 119 GOOG 2700 1
0 w 119
1 w 118
0 B 120 GOOG 2700 1
1 S 121 GOOG 2700 1
0 w 121
1 w 120
0 B 122 GOOG 2700 1
1 S 123 GOOG 2700 1
0 w 123
1 w 122
0 B 124 GOOG 2700 1
1 S 125 GOOG 2700 1
0 w 125
1 w 124
0 B 126 GOOG 2700 1
1 S 127 GOOG 2700 1
0 w 127
1 w 126
0 B 128 GOOG 2700 1
1 S 129 GOOG 2700 1
0 w 129
1 w 128
0 B 130 GOOG 2700 1
1 S 131 GOOG 2700 1
0 w 131
1 w 130
0 B 132 GOOG 2700 1
1 S 133 GOOG 2700 1
0 w 133
1 w 132
0 B 134 GOOG 2700 1
1 S 135 GOOG 2700 1
0 w 135
1 w 134
0 B 136 GOOG 2700 1
1 S 137 GOOG 2700 1
0 w 137
1 w 136
0 B 138 GOOG 2700 1
1 S 139 GOOG 2700 1
0 w 139
1 w 138
0 B 140 GOOG 2700 1
1 S 141 GOOG 2700 1
0 w 141
1 w 140
0 B 142 GOOG 2700 1
1 S 143 GOOG 2700 1
0 w 143
1 w 142
0 B 144 GOOG 2700 1
1 S 145 GOOG 2700 1
0 w 145
1 w 144
0 B 146 GOOG 2700 1
1 S 147 GOOG 2700 1
0 w 147
1 w 146
0 B 148 GOOG 2700 1
1 S 149 GOOG 2700 1
0 w 149
1 w 148
0 B 150 GOOG 2700 1
1 S 151 GOOG 2700 1
0 w 151
1 w 150
0 B 152 GOOG 2700 1
1 S 153 GOOG 2700 1
0 w 153
1 w 152
0 B 154 GOOG 2700 1
1 S 155 GOOG 2700 1
0 w 155
1 w 154
0 B 156 GOOG 2700 1
1 S 157 GOOG 2700 1
0 w 157
1 w 156
0 B 158 GOOG 2700 1
1 S 159 GOOG 2700 1
0 w 159
1 w 158
0 B 160 GOOG 2700 1
1 S 161 GOOG 2700 1
0 w 161
1 w 160
0 B 162 GOOG 2700 1
1 S 163 GOOG 2700 1
0 w 163
1 w 162
0 B 164 GOOG 2700 1
1 S 165 GOOG 2700 1
0 w 165
1 w 164
0 B 166 GOOG 2700 1
1 S 167 GOOG 2700 1
0 w 167
1 w 166
0 B 168 GOOG 2700 1
1 S 169 GOOG 2700 1
0 w 169
1 w 168
0 B 170 GOOG 2700 1
1 S 171 GOOG 2700 1
0 w 171
1 w 170
0 B 172 GOOG 2700 1
1 S 173 GOOG 2700 1
0 w 173
1 w 172
0 B 174 GOOG 2700 1
1 S 175 GOOG 2700 1
0 w 175
1 w 174
0 B 176 GOOG 2700 1
1 S 177 GOOG 2700 1
0 w 177
1 w 176
0 B 178 GOOG 2700 1
1 S 179 GOOG 2700 1
0 w 179
1 w 178
0 B 180 GOOG 2700 1
1 S 181 GOOG 2700 1
0 w 181
1 w 180
0 B 182 GOOG 2700 1
1 S 183 GOOG 2700 1
0 w 183
1 w 182
0 B 184 GOOG 2700 1
1 S 185 GOOG 2700 1
0 w 185
1 w 184
0 B 186 GOOG 2700 1
1 S 187 GOOG 2700 1
0 w 187
1 w 186
0 B 188 GOOG 2700 1
1 S 189 GOOG 2700 1
0 w 189
1 w 188
0 B 190 GOOG 2700 1
1 S 191 GOOG 2700 1
0 w 191
1 w 190
0 B 192 GOOG 2700 1
1 S 193 GOOG 2700 1
0 w 193
1 w 192
0 B 194 GOOG 2700 1
1 S 195 GOOG 2700 1
0 w 195
1 w 194
0 B 196 GOOG 2700 1
1 S 197 GOOG 2700 1
0 w 197
1 w 196
0 B 198 GOOG 2700 1
1 S 199 GOOG 2700 1
0 w 199
1 w 198
0 B 200 GOOG 2700 1
1 S 201 GOOG 2700 1
0 w 201
1 w 200
0 B 202 GOOG 2700 1
1 S 203 GOOG 2700 1
0 w 203
1 w 202
0 B 204 GOOG 2700 1
1 S 205 GOOG 2700 1
0 w 205
1 w 204
0 B 206 GOOG 2700 1
1 S 207 GOOG 2700 1
0 w 207
1 w 206
0 B 208 GOOG 2700 1
1 S 209 GOOG 2700 1
0 w 209
1 w 208
0 B 210 GOOG 2700 1
1 S 211 GOOG 2700 1
0 w 211
1 w 210
0 B 212 GOOG 2700 1
1 S 213 GOOG 2700 1
0 w 213
1 w 212
0 B 214 GOOG 2700 1
1 S 215 GOOG 2700 1
0 w 215
1 w 214
0 B 216 GOOG 2700 1
1 S 217 GOOG 2700 1
0 w 217
1 w 216
0 B 218 GOOG 2700 1
1 S 219 GOOG 2700 1
0 w 219
1 w 218
0 B 220 GOOG 2700 1
1 S 221 GOOG 2700 1
0 w 221
1 w 220
0 B 222 GOOG 2700 1
1 S 223 GOOG 2700 1
0 w 223
1 w 222
0 B 224 GOOG 2700 1
1 S 225 GOOG 2700 1
0 w 225
1 w 224
0 B 226 GOOG 2700 1
1 S 227 GOOG 2700 1
0 w 227
1 w 226
0 B 228 GOOG 2700 1
1 S 229 GOOG 2700 1
0 w 229
1 w 228
0 B 230 GOOG 2700 1
1 S 231 GOOG 2700 1
0 w 231
1 w 230
0 B 232 GOOG 2700 1
1 S 233 GOOG 2700 1
0 w 233
1 w 232
0 B 234 GOOG 2700 1
1 S 235 GOOG 2700 1
0 w 235
1 w 234
0 B 236 GOOG 2700 1
1 S 237 GOOG 2700 1
0 w 237
1 w 236
0 B 238 GOOG 2700 1
1 S 239 GOOG 2700 1
0 w 239
1 w 238
0 B 240 GOOG 2700 1
1 S 241 GOOG 2700 1
0 w 241
1 w 240
0 B 242 GOOG 2700 1
1 S 243 GOOG 2700 1
0 w 243
1 w 242
0 B 244 GOOG 2700 1
1 S 245 GOOG 2700 1
0 w 245
1 w 244
0 B 246 GOOG 2700 1
1 S 247 GOOG 2700 1
0 w 247
1 w 246
0 B 248 GOOG 2700 1
1 S 249 GOOG 2700 1
0 w 249
1 w 248
0 B 250 GOOG 2700 1
1 S 251 GOOG 2700 1
0 w 251
1 w 250
0 B 252 GOOG 2700 1
1 S 253 GOOG 2700 1
0 w 253
1 w 252
0 B 254 GOOG 2700 1
1 S 255 GOOG 2700 1
0 w 255
1 w 254
0 B 256 GOOG 2700 1
1 S 257 GOOG 2700 1
0 w 257
1 w 256
0 B 258 GOOG 2700 1
1 S 259 GOOG 2700 1
0 w 259
1 w 258
0 B 260 GOOG 2700 1
1 S 261 GOOG 2700 1
0 w 261
1 w 260
0 B 262 GOOG 2700 1
1 S 263 GOOG 2700 1
0 w 263
1 w 262
0 B 264 GOOG 2700 1
1 S 265 GOOG 2700 1
0 w 265
1 w 264
0 B 266 GOOG 2700 1
1 S 267 GOOG 2700 1
0 w 267
1 w 266
0 B 268 GOOG 2700 1
1 S 269 GOOG 2700 1
0 w 269
1 w 268
0 B 270 GOOG 2700 1
1 S 271 GOOG 2700 1
0 w 271
1 w 270
0 B 272 GOOG 2700 1
1 S 273 GOOG 2700 1
0 w 273
1 w 272
0 B 274 GOOG 2700 1
1 S 275 GOOG 2700 1
0 w 275
1 w 274
0 B 276 GOOG 2700 1
1 S 277 GOOG 2700 1
0 w 277
1 w 276
0 B 278 GOOG 2700 1
1 S 279 GOOG 2700 1
0 w 279
1 w 278
0 B 280 GOOG 2700 1
1 S 281 GOOG 2700 1
0 w 281
1 w 280
0 B 282 GOOG 2700 1
1 S 283 GOOG 2700 1
0 w 283
1 w 282
0 B 284 GOOG 2700 1
1 S 285 GOOG 2700 1
0 w 285
1 w 284
0 B 286 GOOG 2700 1
1 S 287 GOOG 2700 1
0 w 287
1 w 286
0 B 288 GOOG 2700 1
1 S 289 GOOG 2700 1
0 w 289
1 w 288
0 B 290 GOOG 2700 1
